Workbook
Name UPDATE: 'Data Sheet'!$E$1

Sheet Profit & Loss
A1: ='Data Sheet'!B1 -> TATA MOTORS LTD | H1: =UPDATE | M1: SCREENER.IN
A3: Narration | B3: ='Data Sheet'!B16 -> 42460 | C3: ='Data Sheet'!C16 -> 42825 | D3: ='Data Sheet'!D16 -> 43190 | E3: ='Data Sheet'!E16 -> 43555 | F3: ='Data Sheet'!F16 -> 43921 | G3: ='Data Sheet'!G16 -> 44286 | H3: ='Data Sheet'!H16 -> 44651 | I3: ='Data Sheet'!I16 -> 45016 | ... K3: ='Data Sheet'!K16 -> 45747 | L3: Trailing | M3: Best Case | N3: Worst Case
A4: Sales | B4: ='Data Sheet'!B17 -> 273045.6 | C4: ='Data Sheet'!C17 -> 269692.51 | D4: ='Data Sheet'!D17 -> 291550.48 | E4: ='Data Sheet'!E17 -> 301938.4 | F4: ='Data Sheet'!F17 -> 261067.97 | G4: ='Data Sheet'!G17 -> 249794.75 | H4: ='Data Sheet'!H17 -> 278453.62 | I4: ='Data Sheet'!I17 -> 345966.97 | ... K4: ='Data Sheet'!K17 -> 439695 | L4: =SUM(Quarters!H4:K4) -> 441609 | M4: =$K4+M23*K4 -> 512017.04 | N4: =$K4+N23*L4 -> 445473.35
A5: Expenses | B5: =SUM('Data Sheet'!B18,'Data Sheet'!B20:B24, -1*'Data Sheet'!B19) -> 234650.35 | C5: =SUM('Data Sheet'!C18,'Data Sheet'!C20:C24, -1*'Data Sheet'!C19) -> 240103.82 | D5: =SUM('Data Sheet'!D18,'Data Sheet'!D20:D24, -1*'Data Sheet'!D19) -> 260092.8 | E5: =SUM('Data Sheet'!E18,'Data Sheet'!E20:E24, -1*'Data Sheet'!E19) -> 277274.07 | F5: =SUM('Data Sheet'!F18,'Data Sheet'!F20:F24, -1*'Data Sheet'!F19) -> 243080.9 | G5: =SUM('Data Sheet'!G18,'Data Sheet'!G20:G24, -1*'Data Sheet'!G19) -> 217507.32 | H5: =SUM('Data Sheet'!H18,'Data Sheet'!H20:H24, -1*'Data Sheet'!H19) -> 253733.53 | I5: =SUM('Data Sheet'!I18,'Data Sheet'!I20:I24, -1*'Data Sheet'!I19) -> 314151.17 | ... K5: =SUM('Data Sheet'!K18,'Data Sheet'!K20:K24, -1*'Data Sheet'!K19) -> 384479 | L5: =SUM(Quarters!H5:K5) -> 384424 | M5: =M4-M6 -> 445714.73 | N5: =N4-N6 -> 398338.79
A6: Operating Profit | B6: =B4-B5 -> 38395.25 | C6: =C4-C5 -> 29588.69 | D6: =D4-D5 -> 31457.68 | E6: =E4-E5 -> 24664.33 | F6: =F4-F5 -> 17987.07 | G6: =G4-G5 -> 32287.43 | H6: =H4-H5 -> 24720.09 | I6: =I4-I5 -> 31815.8 | ... K6: =K4-K5 -> 55216 | L6: =SUM(Quarters!H6:K6) -> 57185 | M6: =M4*M24 -> 66302.304 | N6: =N4*N24 -> 47134.558
A7: Other Income | B7: ='Data Sheet'!B25 -> -2669.62 | C7: ='Data Sheet'!C25 -> 1869.1 | D7: ='Data Sheet'!D25 -> 5932.73 | E7: ='Data Sheet'!E25 -> -26686.25 | F7: ='Data Sheet'!F25 -> 101.71 | G7: ='Data Sheet'!G25 -> -11117.83 | H7: ='Data Sheet'!H25 -> 2424.05 | I7: ='Data Sheet'!I25 -> 6663.97 | ... K7: ='Data Sheet'!K25 -> 11774 | L7: =SUM(Quarters!H7:K7) -> 6151 | M7: 0 | N7: 0
A8: Depreciation | B8: ='Data Sheet'!B26 -> 16710.78 | C8: ='Data Sheet'!C26 -> 17904.99 | D8: ='Data Sheet'!D26 -> 21553.59 | E8: ='Data Sheet'!E26 -> 23590.63 | F8: ='Data Sheet'!F26 -> 21425.43 | G8: ='Data Sheet'!G26 -> 23546.71 | H8: ='Data Sheet'!H26 -> 24835.69 | I8: ='Data Sheet'!I26 -> 24860.36 | ... K8: ='Data Sheet'!K26 -> 23256 | L8: =SUM(Quarters!H8:K8) -> 23273 | M8: =+$L8 -> 23273 | N8: =+$L8 -> 23273
A9: Interest | B9: ='Data Sheet'!B27 -> 4889.08 | C9: ='Data Sheet'!C27 -> 4238.01 | D9: ='Data Sheet'!D27 -> 4681.79 | E9: ='Data Sheet'!E27 -> 5758.6 | F9: ='Data Sheet'!F27 -> 7243.33 | G9: ='Data Sheet'!G27 -> 8097.17 | H9: ='Data Sheet'!H27 -> 9311.86 | I9: ='Data Sheet'!I27 -> 10225.48 | ... K9: ='Data Sheet'!K27 -> 5083 | L9: =SUM(Quarters!H9:K9) -> 6317 | M9: =+$L9 -> 6317 | N9: =+$L9 -> 6317
A10: Profit before tax | B10: ='Data Sheet'!B28 -> 14125.77 | C10: ='Data Sheet'!C28 -> 9314.79 | D10: ='Data Sheet'!D28 -> 11155.03 | E10: ='Data Sheet'!E28 -> -31371.15 | F10: ='Data Sheet'!F28 -> -10579.98 | G10: ='Data Sheet'!G28 -> -10474.28 | H10: ='Data Sheet'!H28 -> -7003.41 | I10: ='Data Sheet'!I28 -> 3393.93 | ... K10: ='Data Sheet'!K28 -> 38651 | L10: =SUM(Quarters!H10:K10) -> 33746 | M10: =M6+M7-SUM(M8:M9) -> 36712.304 | N10: =N6+N7-SUM(N8:N9) -> 17544.558
A11: Tax | B11: ='Data Sheet'!B29 -> 3025.05 | C11: ='Data Sheet'!C29 -> 3251.23 | D11: ='Data Sheet'!D29 -> 4341.93 | E11: ='Data Sheet'!E29 -> -2437.45 | F11: ='Data Sheet'!F29 -> 395.25 | G11: ='Data Sheet'!G29 -> 2541.86 | H11: ='Data Sheet'!H29 -> 4231.29 | I11: ='Data Sheet'!I29 -> 704.06 | ... K11: ='Data Sheet'!K29 -> 10502 | L11: =SUM(Quarters!H11:K11) -> 10563 | M11: =IF($L10>0,$L11/$L10,0) -> 0.31301488 | N11: =IF($L10>0,$L11/$L10,0) -> 0.31301488
A12: Net profit | B12: ='Data Sheet'!B30 -> 11579.31 | C12: ='Data Sheet'!C30 -> 7454.36 | D12: ='Data Sheet'!D30 -> 8988.91 | E12: ='Data Sheet'!E30 -> -28826.23 | F12: ='Data Sheet'!F30 -> -12070.85 | G12: ='Data Sheet'!G30 -> -13451.39 | H12: ='Data Sheet'!H30 -> -11441.47 | I12: ='Data Sheet'!I30 -> 2414.29 | ... K12: ='Data Sheet'!K30 -> 27830 | L12: =SUM(Quarters!H12:K12) -> 22785 | M12: =M10-M11*M10 -> 25220.807 | N12: =N10-N11*N10 -> 12052.85
A13: EPS | B13: =IF('Data Sheet'!B93>0,B12/'Data Sheet'!B93,0) -> 40.105673 | C13: =IF('Data Sheet'!C93>0,C12/'Data Sheet'!C93,0) -> 25.817754 | D13: =IF('Data Sheet'!D93>0,D12/'Data Sheet'!D93,0) -> 31.132581 | E13: =IF('Data Sheet'!E93>0,E12/'Data Sheet'!E93,0) -> -99.838015 | F13: =IF('Data Sheet'!F93>0,F12/'Data Sheet'!F93,0) -> -39.076886 | G13: =IF('Data Sheet'!G93>0,G12/'Data Sheet'!G93,0) -> -40.512574 | H13: =IF('Data Sheet'!H93>0,H12/'Data Sheet'!H93,0) -> -34.454994 | I13: =IF('Data Sheet'!I93>0,I12/'Data Sheet'!I93,0) -> 7.2691115 | ... K13: =IF('Data Sheet'!K93>0,K12/'Data Sheet'!K93,0) -> 75.598294 | L13: =IF('Data Sheet'!$B6>0,'Profit & Loss'!L12/'Data Sheet'!$B6,0) -> 61.88227 | M13: =IF('Data Sheet'!$B6>0,'Profit & Loss'!M12/'Data Sheet'!$B6,0) -> 68.49773 | N13: =IF('Data Sheet'!$B6>0,'Profit & Loss'!N12/'Data Sheet'!$B6,0) -> 32.734595
A14: Price to earning | B14: =IF(B15>0,B15/B13,"") -> 9.639534 | C14: =IF(C15>0,C15/C13,"") -> 18.043785 | D14: =IF(D15>0,D15/D13,"") -> 10.498648 | E14: =IF(E15>0,E15/E13,"") -> -1.7453272 | F14: =IF(F15>0,F15/F13,"") -> -1.8182104 | G14: =IF(G15>0,G15/G13,"") -> -7.449539 | H14: =IF(H15>0,H15/H13,"") -> -12.588886 | I14: =IF(I15>0,I15/I13,"") -> 57.888781 | ... K14: =IF(K15>0,K15/K13,"") -> 8.9214976 | L14: =IF(L13>0,L15/L13,0) -> 11.014463 | M14: =M25 -> 22.083474 | N14: =N25 -> 11.014463
A15: Price | B15: ='Data Sheet'!B90 -> 386.6 | C15: ='Data Sheet'!C90 -> 465.85 | D15: ='Data Sheet'!D90 -> 326.85 | E15: ='Data Sheet'!E90 -> 174.25 | F15: ='Data Sheet'!F90 -> 71.05 | G15: ='Data Sheet'!G90 -> 301.8 | H15: ='Data Sheet'!H90 -> 433.75 | I15: ='Data Sheet'!I90 -> 420.8 | ... K15: ='Data Sheet'!K90 -> 674.45 | L15: ='Data Sheet'!B8 -> 681.6 | M15: =M13*M14 -> 1512.6678 | N15: =N13*N14 -> 360.554
A17: RATIOS:
A18: Dividend Payout | B18: =IF('Data Sheet'!B30>0, 'Data Sheet'!B31/'Data Sheet'!B30, 0) -> 0.0058656345 | C18: =IF('Data Sheet'!C30>0, 'Data Sheet'!C31/'Data Sheet'!C30, 0) -> 0 | D18: =IF('Data Sheet'!D30>0, 'Data Sheet'!D31/'Data Sheet'!D30, 0) -> 0 | E18: =IF('Data Sheet'!E30>0, 'Data Sheet'!E31/'Data Sheet'!E30, 0) -> 0 | F18: =IF('Data Sheet'!F30>0, 'Data Sheet'!F31/'Data Sheet'!F30, 0) -> 0 | G18: =IF('Data Sheet'!G30>0, 'Data Sheet'!G31/'Data Sheet'!G30, 0) -> 0 | H18: =IF('Data Sheet'!H30>0, 'Data Sheet'!H31/'Data Sheet'!H30, 0) -> 0 | I18: =IF('Data Sheet'!I30>0, 'Data Sheet'!I31/'Data Sheet'!I30, 0) -> 0.31728583 | ... K18: =IF('Data Sheet'!K30>0, 'Data Sheet'!K31/'Data Sheet'!K30, 0) -> 0.079338843
A19: OPM | B19: =IF(B6>0,B6/B4,0) -> 0.14061845 | C19: =IF(C6>0,C6/C4,0) -> 0.10971269 | D19: =IF(D6>0,D6/D4,0) -> 0.10789788 | E19: =IF(E6>0,E6/E4,0) -> 0.081686629 | F19: =IF(F6>0,F6/F4,0) -> 0.068898034 | G19: =IF(G6>0,G6/G4,0) -> 0.12925584 | H19: =IF(H6>0,H6/H4,0) -> 0.088776328 | I19: =IF(I6>0,I6/I4,0) -> 0.091961958 | ... L19: =IF(L6>0,L6/L4,0) -> 0.12949238
G22: TRENDS: | H22: 10 YEARS | I22: 7 YEARS | J22: 5 YEARS | K22: 3 YEARS | L22: RECENT | M22: BEST | N22: WORST
G23: Sales Growth | H23: =IF(B4=0,"",POWER($K4/B4,1/9)-1) -> 0.05436433 | I23: =IF(D4=0,"",POWER($K4/D4,1/7)-1) -> 0.060452229 | J23: =IF(F4=0,"",POWER($K4/F4,1/5)-1) -> 0.1098891 | K23: =IF(H4=0,"",POWER($K4/H4, 1/3)-1) -> 0.16448229 | L23: =IF(ISERROR(MAX(IF(J4=0,"",(K4-J4)/J4),IF(K4=0,"",(L4-K4)/K4))),"",MAX(IF(J4=0,"",(K4-J4)/J4),IF(K4=0,"",(L4-K4)/K4))) -> 0.013084771 | M23: =MAX(K23:L23) -> 0.16448229 | N23: =MIN(H23:L23) -> 0.013084771
G24: OPM | H24: =IF(SUM(B4:$K$4)=0,"",SUMPRODUCT(B19:$K$19,B4:$K$4)/SUM(B4:$K$4)) -> 0.10935839 | I24: =IF(SUM(E4:$K$4)=0,"",SUMPRODUCT(E19:$K$19,E4:$K$4)/SUM(E4:$K$4)) -> 0.10580781 | J24: =IF(SUM(G4:$K$4)=0,"",SUMPRODUCT(G19:$K$19,G4:$K$4)/SUM(G4:$K$4)) -> 0.11548732 | K24: =IF(SUM(I4:$K$4)=0, "", SUMPRODUCT(I19:$K$19,I4:$K$4)/SUM(I4:$K$4)) -> 0.11876561 | L24: =L19 -> 0.12949238 | M24: =MAX(K24:L24) -> 0.12949238 | N24: =MIN(H24:L24) -> 0.10580781
G25: Price to Earning | H25: =IF(ISERROR(AVERAGEIF(B14:$L14,">0")),"",AVERAGEIF(B14:$L14,">0")) -> 18.073695 | I25: =IF(ISERROR(AVERAGEIF(E14:$L14,">0")),"",AVERAGEIF(E14:$L14,">0")) -> 22.083474 | J25: =IF(ISERROR(AVERAGEIF(G14:$L14,">0")),"",AVERAGEIF(G14:$L14,">0")) -> 22.083474 | K25: =IF(ISERROR(AVERAGEIF(I14:$L14,">0")),"",AVERAGEIF(I14:$L14,">0")) -> 22.083474 | L25: =L14 -> 11.014463 | M25: =MAX(K25:L25) -> 22.083474 | N25: =MIN(H25:L25) -> 11.014463

Sheet Quarters
A1: ='Profit & Loss'!A1 -> TATA MOTORS LTD | E1: =UPDATE | J1: SCREENER.IN
A3: Narration | B3: ='Data Sheet'!B41 -> 44926 | C3: ='Data Sheet'!C41 -> 45016 | D3: ='Data Sheet'!D41 -> 45107 | E3: ='Data Sheet'!E41 -> 45199 | F3: ='Data Sheet'!F41 -> 45291 | G3: ='Data Sheet'!G41 -> 45382 | H3: ='Data Sheet'!H41 -> 45473 | I3: ='Data Sheet'!I41 -> 45565 | ... K3: ='Data Sheet'!K41 -> 45747
A4: Sales | B4: ='Data Sheet'!B42 -> 88488.59 | C4: ='Data Sheet'!C42 -> 105932.35 | D4: ='Data Sheet'!D42 -> 102236 | E4: ='Data Sheet'!E42 -> 105129 | F4: ='Data Sheet'!F42 -> 110577 | G4: ='Data Sheet'!G42 -> 119033 | H4: ='Data Sheet'!H42 -> 108048 | I4: ='Data Sheet'!I42 -> 101450 | ... K4: ='Data Sheet'!K42 -> 119503
A5: Expenses | B5: ='Data Sheet'!B43 -> 77668.35 | C5: ='Data Sheet'!C43 -> 92817.95 | D5: ='Data Sheet'!D43 -> 89019 | E5: ='Data Sheet'!E43 -> 91362 | F5: ='Data Sheet'!F43 -> 95159 | G5: ='Data Sheet'!G43 -> 102348 | H5: ='Data Sheet'!H43 -> 92263 | I5: ='Data Sheet'!I43 -> 89291 | ... K5: ='Data Sheet'!K43 -> 102685
A6: Operating Profit | B6: ='Data Sheet'!B50 -> 10820.24 | C6: ='Data Sheet'!C50 -> 13114.4 | D6: ='Data Sheet'!D50 -> 13217 | E6: ='Data Sheet'!E50 -> 13767 | F6: ='Data Sheet'!F50 -> 15418 | G6: ='Data Sheet'!G50 -> 16685 | H6: ='Data Sheet'!H50 -> 15785 | I6: ='Data Sheet'!I50 -> 12159 | ... K6: ='Data Sheet'!K50 -> 16818
A7: Other Income | B7: ='Data Sheet'!B44 -> 1129.98 | C7: ='Data Sheet'!C44 -> 1452.86 | D7: ='Data Sheet'!D44 -> 895 | E7: ='Data Sheet'!E44 -> 1557 | F7: ='Data Sheet'!F44 -> 1604 | G7: ='Data Sheet'!G44 -> 1412 | H7: ='Data Sheet'!H44 -> 1747 | I7: ='Data Sheet'!I44 -> 1647 | ... K7: ='Data Sheet'!K44 -> 1057
A8: Depreciation | B8: ='Data Sheet'!B45 -> 6071.78 | C8: ='Data Sheet'!C45 -> 7050.2 | D8: ='Data Sheet'!D45 -> 6633 | E8: ='Data Sheet'!E45 -> 6637 | F8: ='Data Sheet'!F45 -> 6850 | G8: ='Data Sheet'!G45 -> 7143 | H8: ='Data Sheet'!H45 -> 6574 | I8: ='Data Sheet'!I45 -> 6005 | ... K8: ='Data Sheet'!K45 -> 5295
A9: Interest | B9: ='Data Sheet'!B46 -> 2675.83 | C9: ='Data Sheet'!C46 -> 2641.67 | D9: ='Data Sheet'!D46 -> 2615 | E9: ='Data Sheet'!E46 -> 2652 | F9: ='Data Sheet'!F46 -> 2485 | G9: ='Data Sheet'!G46 -> 1645 | H9: ='Data Sheet'!H46 -> 2088 | I9: ='Data Sheet'!I46 -> 2034 | ... K9: ='Data Sheet'!K46 -> 1076
A10: Profit before tax | B10: ='Data Sheet'!B47 -> 3202.61 | C10: ='Data Sheet'!C47 -> 4875.39 | D10: ='Data Sheet'!D47 -> 4864 | E10: ='Data Sheet'!E47 -> 6035 | F10: ='Data Sheet'!F47 -> 7687 | G10: ='Data Sheet'!G47 -> 9309 | H10: ='Data Sheet'!H47 -> 8870 | I10: ='Data Sheet'!I47 -> 5767 | ... K10: ='Data Sheet'!K47 -> 11504
A11: Tax | B11: ='Data Sheet'!B48 -> 262.83 | C11: ='Data Sheet'!C48 -> -620.65 | D11: ='Data Sheet'!D48 -> 1563 | E11: ='Data Sheet'!E48 -> 2203 | F11: ='Data Sheet'!F48 -> 542 | G11: ='Data Sheet'!G48 -> -8219 | H11: ='Data Sheet'!H48 -> 3178 | I11: ='Data Sheet'!I48 -> 2317 | ... K11: ='Data Sheet'!K48 -> 2948
A12: Net profit | B12: ='Data Sheet'!B49 -> 2957.71 | C12: ='Data Sheet'!C49 -> 5407.79 | D12: ='Data Sheet'!D49 -> 3203 | E12: ='Data Sheet'!E49 -> 3764 | F12: ='Data Sheet'!F49 -> 7025 | G12: ='Data Sheet'!G49 -> 17407 | H12: ='Data Sheet'!H49 -> 5566 | I12: ='Data Sheet'!I49 -> 3343 | ... K12: ='Data Sheet'!K49 -> 8470
A14: OPM | B14: =IF(B4>0,B6/B4,"") -> 0.12227836 | C14: =IF(C4>0,C6/C4,"") -> 0.12379976 | D14: =IF(D4>0,D6/D4,"") -> 0.12927931 | E14: =IF(E4>0,E6/E4,"") -> 0.1309534 | F14: =IF(F4>0,F6/F4,"") -> 0.13943225 | G14: =IF(G4>0,G6/G4,"") -> 0.14017121 | H14: =IF(H4>0,H6/H4,"") -> 0.14609248 | I14: =IF(I4>0,I6/I4,"") -> 0.11985214 | ... K14: =IF(K4>0,K6/K4,"") -> 0.14073287

Sheet Balance Sheet
A1: ='Profit & Loss'!A1 -> TATA MOTORS LTD | E1: =UPDATE | J1: SCREENER.IN
A3: Narration | B3: ='Data Sheet'!B56 -> 42460 | C3: ='Data Sheet'!C56 -> 42825 | D3: ='Data Sheet'!D56 -> 43190 | E3: ='Data Sheet'!E56 -> 43555 | F3: ='Data Sheet'!F56 -> 43921 | G3: ='Data Sheet'!G56 -> 44286 | H3: ='Data Sheet'!H56 -> 44651 | I3: ='Data Sheet'!I56 -> 45016 | ... K3: ='Data Sheet'!K56 -> 45747 | L3: 45901
A4: Equity Share Capital | B4: ='Data Sheet'!B57 -> 679.18 | C4: ='Data Sheet'!C57 -> 679.22 | D4: ='Data Sheet'!D57 -> 679.22 | E4: ='Data Sheet'!E57 -> 679.22 | F4: ='Data Sheet'!F57 -> 719.54 | G4: ='Data Sheet'!G57 -> 765.81 | H4: ='Data Sheet'!H57 -> 765.88 | I4: ='Data Sheet'!I57 -> 766.02 | ... K4: ='Data Sheet'!K57 -> 736 | L4: 736
A5: Reserves | B5: ='Data Sheet'!B58 -> 78273.23 | C5: ='Data Sheet'!C58 -> 57382.67 | D5: ='Data Sheet'!D58 -> 94748.69 | E5: ='Data Sheet'!E58 -> 59500.34 | F5: ='Data Sheet'!F58 -> 62358.99 | G5: ='Data Sheet'!G58 -> 54480.91 | H5: ='Data Sheet'!H58 -> 43795.36 | I5: ='Data Sheet'!I58 -> 44555.77 | ... K5: ='Data Sheet'!K58 -> 115408 | L5: 9708
A6: Borrowings | B6: ='Data Sheet'!B59 -> 69359.96 | C6: ='Data Sheet'!C59 -> 78603.98 | D6: ='Data Sheet'!D59 -> 88950.47 | E6: ='Data Sheet'!E59 -> 106175.34 | F6: ='Data Sheet'!F59 -> 124787.64 | G6: ='Data Sheet'!G59 -> 142130.57 | H6: ='Data Sheet'!H59 -> 146449.03 | I6: ='Data Sheet'!I59 -> 134113.44 | ... K6: ='Data Sheet'!K59 -> 71540 | L6: 5983
A7: Other Liabilities | B7: ='Data Sheet'!B60 -> 114871.75 | C7: ='Data Sheet'!C60 -> 135914.49 | D7: ='Data Sheet'!D60 -> 142813.43 | E7: ='Data Sheet'!E60 -> 139348.59 | F7: ='Data Sheet'!F60 -> 132313.22 | G7: ='Data Sheet'!G60 -> 144192.62 | H7: ='Data Sheet'!H60 -> 138051.22 | I7: ='Data Sheet'!I60 -> 155239.2 | ... K7: ='Data Sheet'!K60 -> 189289 | L7: 22446
A8: Total | B8: ='Data Sheet'!B61 -> 263184.12 | C8: ='Data Sheet'!C61 -> 272580.36 | D8: ='Data Sheet'!D61 -> 327191.81 | E8: ='Data Sheet'!E61 -> 305703.49 | F8: ='Data Sheet'!F61 -> 320179.39 | G8: ='Data Sheet'!G61 -> 341569.91 | H8: ='Data Sheet'!H61 -> 329061.49 | I8: ='Data Sheet'!I61 -> 334674.43 | ... K8: ='Data Sheet'!K61 -> 376973 | L8: 38873
A10: Net Block | B10: ='Data Sheet'!B62 -> 107231.76 | C10: ='Data Sheet'!C62 -> 95944.08 | D10: ='Data Sheet'!D62 -> 121413.86 | E10: ='Data Sheet'!E62 -> 111234.47 | F10: ='Data Sheet'!F62 -> 127107.14 | G10: ='Data Sheet'!G62 -> 138707.61 | H10: ='Data Sheet'!H62 -> 138855.45 | I10: ='Data Sheet'!I62 -> 132079.76 | ... K10: ='Data Sheet'!K62 -> 115697 | L10: 13021
A11: Capital Work in Progress | B11: ='Data Sheet'!B63 -> 25918.94 | C11: ='Data Sheet'!C63 -> 33698.84 | D11: ='Data Sheet'!D63 -> 40033.5 | E11: ='Data Sheet'!E63 -> 31883.84 | F11: ='Data Sheet'!F63 -> 35622.29 | G11: ='Data Sheet'!G63 -> 20963.93 | H11: ='Data Sheet'!H63 -> 10251.09 | I11: ='Data Sheet'!I63 -> 14274.5 | ... K11: ='Data Sheet'!K63 -> 65806 | L11: 626
A12: Investments | B12: ='Data Sheet'!B64 -> 23767.02 | C12: ='Data Sheet'!C64 -> 20337.92 | D12: ='Data Sheet'!D64 -> 20812.75 | E12: ='Data Sheet'!E64 -> 15770.72 | F12: ='Data Sheet'!F64 -> 16308.48 | G12: ='Data Sheet'!G64 -> 24620.28 | H12: ='Data Sheet'!H64 -> 29379.53 | I12: ='Data Sheet'!I64 -> 26379.16 | ... K12: ='Data Sheet'!K64 -> 35656 | L12: 9590
A13: Other Assets | B13: ='Data Sheet'!B65 -> 106266.4 | C13: ='Data Sheet'!C65 -> 122599.52 | D13: ='Data Sheet'!D65 -> 144931.7 | E13: ='Data Sheet'!E65 -> 146814.46 | F13: ='Data Sheet'!F65 -> 141141.48 | G13: ='Data Sheet'!G65 -> 157278.09 | H13: ='Data Sheet'!H65 -> 150575.42 | I13: ='Data Sheet'!I65 -> 161941.01 | ... K13: ='Data Sheet'!K65 -> 159814 | L13: 15636
A14: Total | B14: ='Data Sheet'!B66 -> 263184.12 | C14: ='Data Sheet'!C66 -> 272580.36 | D14: ='Data Sheet'!D66 -> 327191.81 | E14: ='Data Sheet'!E66 -> 305703.49 | F14: ='Data Sheet'!F66 -> 320179.39 | G14: ='Data Sheet'!G66 -> 341569.91 | H14: ='Data Sheet'!H66 -> 329061.49 | I14: ='Data Sheet'!I66 -> 334674.43 | ... K14: ='Data Sheet'!K66 -> 376973 | L14: 38873
A16: Working Capital | B16: =B13-B7 -> -8605.35 | C16: =C13-C7 -> -13314.97 | D16: =D13-D7 -> 2118.27 | E16: =E13-E7 -> 7465.87 | F16: =F13-F7 -> 8828.26 | G16: =G13-G7 -> 13085.47 | H16: =H13-H7 -> 12524.2 | I16: =I13-I7 -> 6701.81 | ... K16: =K13-K7 -> -29475
A17: Debtors | B17: ='Data Sheet'!B67 -> 13570.91 | C17: ='Data Sheet'!C67 -> 14075.55 | D17: ='Data Sheet'!D67 -> 19893.3 | E17: ='Data Sheet'!E67 -> 18996.17 | F17: ='Data Sheet'!F67 -> 11172.69 | G17: ='Data Sheet'!G67 -> 12679.08 | H17: ='Data Sheet'!H67 -> 12442.12 | I17: ='Data Sheet'!I67 -> 15737.97 | ... K17: ='Data Sheet'!K67 -> 13248
A18: Inventory | B18: ='Data Sheet'!B68 -> 32655.73 | C18: ='Data Sheet'!C68 -> 35085.31 | D18: ='Data Sheet'!D68 -> 42137.63 | E18: ='Data Sheet'!E68 -> 39013.73 | F18: ='Data Sheet'!F68 -> 37456.88 | G18: ='Data Sheet'!G68 -> 36088.59 | H18: ='Data Sheet'!H68 -> 35240.34 | I18: ='Data Sheet'!I68 -> 40755.39 | ... K18: ='Data Sheet'!K68 -> 47269
A20: Debtor Days | B20: =IF('Profit & Loss'!B4>0,'Balance Sheet'!B17/('Profit & Loss'!B4/365),0) -> 18.141227 | C20: =IF('Profit & Loss'!C4>0,'Balance Sheet'!C17/('Profit & Loss'!C4/365),0) -> 19.049753 | D20: =IF('Profit & Loss'!D4>0,'Balance Sheet'!D17/('Profit & Loss'!D4/365),0) -> 24.904965 | E20: =IF('Profit & Loss'!E4>0,'Balance Sheet'!E17/('Profit & Loss'!E4/365),0) -> 22.963631 | F20: =IF('Profit & Loss'!F4>0,'Balance Sheet'!F17/('Profit & Loss'!F4/365),0) -> 15.620575 | G20: =IF('Profit & Loss'!G4>0,'Balance Sheet'!G17/('Profit & Loss'!G4/365),0) -> 18.526667 | H20: =IF('Profit & Loss'!H4>0,'Balance Sheet'!H17/('Profit & Loss'!H4/365),0) -> 16.309265 | I20: =IF('Profit & Loss'!I4>0,'Balance Sheet'!I17/('Profit & Loss'!I4/365),0) -> 16.603779 | ... K20: =IF('Profit & Loss'!K4>0,'Balance Sheet'!K17/('Profit & Loss'!K4/365),0) -> 10.997441
A21: Inventory Turnover | B21: =IF('Balance Sheet'!B18>0,'Profit & Loss'!B4/'Balance Sheet'!B18,0) -> 8.3613381 | C21: =IF('Balance Sheet'!C18>0,'Profit & Loss'!C4/'Balance Sheet'!C18,0) -> 7.6867643 | D21: =IF('Balance Sheet'!D18>0,'Profit & Loss'!D4/'Balance Sheet'!D18,0) -> 6.9190052 | E21: =IF('Balance Sheet'!E18>0,'Profit & Loss'!E4/'Balance Sheet'!E18,0) -> 7.7392856 | F21: =IF('Balance Sheet'!F18>0,'Profit & Loss'!F4/'Balance Sheet'!F18,0) -> 6.9698269 | G21: =IF('Balance Sheet'!G18>0,'Profit & Loss'!G4/'Balance Sheet'!G18,0) -> 6.9217099 | H21: =IF('Balance Sheet'!H18>0,'Profit & Loss'!H4/'Balance Sheet'!H18,0) -> 7.9015588 | I21: =IF('Balance Sheet'!I18>0,'Profit & Loss'!I4/'Balance Sheet'!I18,0) -> 8.4888642 | ... K21: =IF('Balance Sheet'!K18>0,'Profit & Loss'!K4/'Balance Sheet'!K18,0) -> 9.3019738
A23: Return on Equity | B23: =IF(SUM('Balance Sheet'!B4:B5)>0,'Profit & Loss'!B12/SUM('Balance Sheet'!B4:B5),"") -> 0.14666189 | C23: =IF(SUM('Balance Sheet'!C4:C5)>0,'Profit & Loss'!C12/SUM('Balance Sheet'!C4:C5),"") -> 0.12838645 | D23: =IF(SUM('Balance Sheet'!D4:D5)>0,'Profit & Loss'!D12/SUM('Balance Sheet'!D4:D5),"") -> 0.094195818 | E23: =IF(SUM('Balance Sheet'!E4:E5)>0,'Profit & Loss'!E12/SUM('Balance Sheet'!E4:E5),"") -> -0.47900367 | F23: =IF(SUM('Balance Sheet'!F4:F5)>0,'Profit & Loss'!F12/SUM('Balance Sheet'!F4:F5),"") -> -0.19136226 | G23: =IF(SUM('Balance Sheet'!G4:G5)>0,'Profit & Loss'!G12/SUM('Balance Sheet'!G4:G5),"") -> -0.24347853 | H23: =IF(SUM('Balance Sheet'!H4:H5)>0,'Profit & Loss'!H12/SUM('Balance Sheet'!H4:H5),"") -> -0.25675834 | I23: =IF(SUM('Balance Sheet'!I4:I5)>0,'Profit & Loss'!I12/SUM('Balance Sheet'!I4:I5),"") -> 0.053269961 | ... K23: =IF(SUM('Balance Sheet'!K4:K5)>0,'Profit & Loss'!K12/SUM('Balance Sheet'!K4:K5),"") -> 0.23961634
A24: Return on Capital Emp | C24: =IF((B4+B5+B6+C4+C5+C6)>0,('Profit & Loss'!C10+'Profit & Loss'!C9)*2/(B4+B5+B6+C4+C5+C6),"") -> 0.095114631 | D24: =IF((C4+C5+C6+D4+D5+D6)>0,('Profit & Loss'!D10+'Profit & Loss'!D9)*2/(C4+C5+C6+D4+D5+D6),"") -> 0.098658176 | E24: =IF((D4+D5+D6+E4+E5+E6)>0,('Profit & Loss'!E10+'Profit & Loss'!E9)*2/(D4+D5+D6+E4+E5+E6),"") -> -0.14605144 | F24: =IF((E4+E5+E6+F4+F5+F6)>0,('Profit & Loss'!F10+'Profit & Loss'!F9)*2/(E4+E5+E6+F4+F5+F6),"") -> -0.018839365 | G24: =IF((F4+F5+F6+G4+G5+G6)>0,('Profit & Loss'!G10+'Profit & Loss'!G9)*2/(F4+F5+F6+G4+G5+G6),"") -> -0.012340819 | H24: =IF((G4+G5+G6+H4+H5+H6)>0,('Profit & Loss'!H10+'Profit & Loss'!H9)*2/(G4+G5+G6+H4+H5+H6),"") -> 0.011887353 | I24: =IF((H4+H5+H6+I4+I5+I6)>0,('Profit & Loss'!I10+'Profit & Loss'!I9)*2/(H4+H5+H6+I4+I5+I6),"") -> 0.073529898 | J24: =IF((I4+I5+I6+J4+J5+J6)>0,('Profit & Loss'!J10+'Profit & Loss'!J9)*2/(I4+I5+I6+J4+J5+J6),"") -> 0.19039483 | K24: =IF((J4+J5+J6+K4+K5+K6)>0,('Profit & Loss'!K10+'Profit & Loss'!K9)*2/(J4+J5+J6+K4+K5+K6),"") -> 0.23026014
C29: 46290
A30: Equity Capital | B30: 0.1 | C30: 736
A31: Reserves | B31: -0.08 | C31: 9708
A32: Borrowings - | B32: 0 | C32: 5983
A33: Long term Borrowings | B33: 0 | C33: 1881
A34: Short term Borrowings | B34: 0 | C34: 3741
A35: Lease Liabilities | B35: 0 | C35: 361
A36: Other Liabilities - | B36: 0.08 | C36: 22446
A37: Trade Payables | B37: 0 | C37: 13260
A38: Other liability items | B38: 0 | C38: 9186
A39: Total Liabilities | B39: 0.1 | C39: 38873
A40: Fixed Assets - | B40: 0 | C40: 13021
A41: Intangible Assets | B41: 0 | C41: 3221
... A50: Total Assets | B50: 0.1 | C50: 38873

Sheet cash flow screener
B1: 41699 | C1: 42064 | D1: 42430 | E1: 42795 | F1: 43160 | G1: 43525 | H1: 43891 | I1: 44256 | J1: 44621 | K1: 44986 | L1: 45352 | M1: 45717
A2: Cash from Operating Activity - | B2: 36151 | C2: 35531 | D2: 37900 | E2: 30199 | F2: 23857 | G2: 18891 | H2: 26633 | I2: 29001 | J2: 14283 | K2: 35388 | L2: 67915 | M2: 63102
A3: Profit from operations | B3: 36303 | C3: 43397 | D3: 38626 | E3: 28840 | F3: 33312 | G3: 28771 | H3: 23352 | I3: 31198 | J3: 26943 | K3: 41694 | L3: 65106 | M3: 58937
A4: Receivables | B4: 445 | C4: -3179 | D4: -2223 | E4: -4152 | F4: -10688 | G4: -9109 | H4: 9950 | I4: -5505 | J4: 185 | K4: -2213 | L4: -1876 | M4: 3573
A5: Inventory | B5: -2853 | C5: -3692 | D5: -5743 | E5: -6621 | F5: -3560 | G5: 2069 | H5: 2326 | I5: 3814 | J5: 472 | K5: -5665 | L5: -7265 | M5: 2127
A6: Payables | B6: 4694 | C6: 3598 | D6: 3947 | E6: 9301 | F6: 7320 | G6: -4692 | H6: -8085 | I6: 5748 | J6: -7012 | K6: 6945 | L6: 13706 | M6: 1303
A7: Loans Advances | B7: 0 | C7: 0 | D7: -520 | E7: 0 | F7: 0 | G7: 0 | H7: 0 | I7: 0 | J7: 0 | K7: 0 | L7: 0 | M7: 0
A8: Other WC items | B8: 1870 | C8: -398 | D8: 5852 | E8: 4727 | F8: 494 | G8: 4512 | H8: 875 | I8: -4150 | J8: -4396 | K8: -2194 | L8: 2760 | M8: 1153
A9: Working capital changes | B9: 4157 | C9: -3672 | D9: 1313 | E9: 3254 | F9: -6434 | G9: -7221 | H9: 5065 | I9: -93 | J9: -10750 | K9: -3127 | L9: 7325 | M9: 8156
A10: Direct taxes | B10: -4308 | C10: -4194 | D10: -2040 | E10: -1895 | F10: -3021 | G10: -2659 | H10: -1785 | I10: -2105 | J10: -1910 | K10: -3179 | L10: -4516 | M10: -3991
A11: Cash from Investing Activity - | B11: -27991 | C11: -36232 | D11: -36694 | E11: -39571 | F11: -25139 | G11: -20878 | H11: -33115 | I11: -25672 | J11: -4444 | K11: -15417 | L11: -22781 | M11: -49982
A12: Fixed assets purchased | B12: -26975 | C12: -31962 | D12: -31503 | E12: -16072 | F12: -35079 | G12: -35304 | H12: -29702 | I12: -20205 | J12: -15168 | K12: -19230 | L12: -31414 | M12: -38042
A13: Fixed assets sold | B13: 50 | C13: 74 | D13: 59 | E13: 53 | F13: 30 | G13: 67 | H13: 171 | I13: 351 | J13: 230 | K13: 285 | L13: 231 | M13: 974
... A32: Net Cash Flow | B32: 4277 | C32: 4500 | D32: -2589 | E32: -3167 | F32: 730 | G32: 6843 | H32: -3092 | I32: 13232 | J32: 6459 | K32: -6272 | L32: 8128 | M32: -5666

Sheet Data Sheet
A1: COMPANY NAME | B1: TATA MOTORS LTD | E1: =IF(B2<>B3, "A NEW VERSION OF THE WORKSHEET IS AVAILABLE", "")
A2: LATEST VERSION | B2: 2.1 | E2: PLEASE DO NOT MAKE ANY CHANGES TO THIS SHEET
A3: CURRENT VERSION | B3: 2.1
A5: META
A6: Number of shares | B6: =IF(B9>0, B9/B8, 0) -> 368.19916
A7: Face Value | B7: 2
A8: Current Price | B8: 681.6
A9: Market Capitalization | B9: 250964.55
A15: PROFIT & LOSS
A16: Report Date | B16: 42460 | C16: 42825 | D16: 43190 | E16: 43555 | F16: 43921 | G16: 44286 | H16: 44651 | I16: 45016 | J16: 45382 | K16: 45747
A17: Sales | B17: 273045.6 | C17: 269692.51 | D17: 291550.48 | E17: 301938.4 | F17: 261067.97 | G17: 249794.75 | H17: 278453.62 | I17: 345966.97 | J17: 434016 | K17: 439695
A18: Raw Material Cost | B18: 166134.01 | C18: 173294.08 | D18: 187896.58 | E18: 194267.91 | F18: 164899.82 | G18: 153607.36 | H18: 179295.33 | I18: 231251.26 | J18: 274321 | K18: 268950
A19: Change in Inventory | B19: 2750.99 | C19: 7399.92 | D19: 2046.58 | E19: -2053.28 | F19: -2231.19 | G19: -4684.16 | H19: -1590.49 | I19: 4781.62 | J19: 1566 | K19: -2836
A20: Power and Fuel | B20: 1143.63 | C20: 1159.82 | D20: 1308.08 | E20: 1585.93 | F20: 1264.95 | G20: 1112.87 | H20: 2178.29 | I20: 2513.33 | J20: 2189 | K20: 2443
A21: Other Mfr. Exp | B21: 12101.53 | C21: 10067.37 | D21: 10971.66 | E21: 11694.54 | F21: 11541.51 | G21: 8273.17 | H21: 9427.38 | I21: 11765.97 | J21: 17446 | K21: 18813
A22: Employee Cost | B22: 28880.89 | C22: 28332.89 | D22: 30300.09 | E22: 33243.87 | F22: 30438.6 | G22: 27648.48 | H22: 30808.52 | I22: 33654.7 | J22: 41990 | K22: 47767
A23: Selling and admin | B23: 21991.9 | C23: 30039.38 | D23: 31004.58 | E23: 32719.8 | F23: 29248.32 | G23: 23015.79 | H23: 29205.4 | I23: 34839.19 | J23: 42765 | K23: 47099
A24: Other Expenses | B24: 7149.38 | C24: 4610.2 | D24: 658.39 | E24: 1708.74 | F24: 3456.51 | G24: -834.51 | H24: 1228.12 | I24: 4908.34 | J24: -953 | K24: -3429
A25: Other Income | B25: -2669.62 | C25: 1869.1 | D25: 5932.73 | E25: -26686.25 | F25: 101.71 | G25: -11117.83 | H25: 2424.05 | I25: 6663.97 | J25: 4792 | K25: 11774
A26: Depreciation | B26: 16710.78 | C26: 17904.99 | D26: 21553.59 | E26: 23590.63 | F26: 21425.43 | G26: 23546.71 | H26: 24835.69 | I26: 24860.36 | J26: 27239 | K26: 23256
A27: Interest | B27: 4889.08 | C27: 4238.01 | D27: 4681.79 | E27: 5758.6 | F27: 7243.33 | G27: 8097.17 | H27: 9311.86 | I27: 10225.48 | J27: 7594 | K27: 5083
... A30: Net profit | B30: 11579.31 | C30: 7454.36 | D30: 8988.91 | E30: -28826.23 | F30: -12070.85 | G30: -13451.39 | H30: -11441.47 | I30: 2414.29 | J30: 31399 | K30: 27830
A31: Dividend Amount | B31: 67.92 | I31: 766.02 | J31: 2301 | K31: 2208
A40: Quarters
A41: Report Date | B41: 44926 | C41: 45016 | D41: 45107 | E41: 45199 | F41: 45291 | G41: 45382 | H41: 45473 | I41: 45565 | J41: 45657 | K41: 45747
A42: Sales | B42: 88488.59 | C42: 105932.35 | D42: 102236 | E42: 105129 | F42: 110577 | G42: 119033 | H42: 108048 | I42: 101450 | J42: 112608 | K42: 119503
A43: Expenses | B43: 77668.35 | C43: 92817.95 | D43: 89019 | E43: 91362 | F43: 95159 | G43: 102348 | H43: 92263 | I43: 89291 | J43: 100185 | K43: 102685
A44: Other Income | B44: 1129.98 | C44: 1452.86 | D44: 895 | E44: 1557 | F44: 1604 | G44: 1412 | H44: 1747 | I44: 1647 | J44: 1700 | K44: 1057
A45: Depreciation | B45: 6071.78 | C45: 7050.2 | D45: 6633 | E45: 6637 | F45: 6850 | G45: 7143 | H45: 6574 | I45: 6005 | J45: 5399 | K45: 5295
A46: Interest | B46: 2675.83 | C46: 2641.67 | D46: 2615 | E46: 2652 | F46: 2485 | G46: 1645 | H46: 2088 | I46: 2034 | J46: 1119 | K46: 1076
A47: Profit before tax | B47: 3202.61 | C47: 4875.39 | D47: 4864 | E47: 6035 | F47: 7687 | G47: 9309 | H47: 8870 | I47: 5767 | J47: 7605 | K47: 11504
A48: Tax | B48: 262.83 | C48: -620.65 | D48: 1563 | E48: 2203 | F48: 542 | G48: -8219 | H48: 3178 | I48: 2317 | J48: 2120 | K48: 2948
A49: Net profit | B49: 2957.71 | C49: 5407.79 | D49: 3203 | E49: 3764 | F49: 7025 | G49: 17407 | H49: 5566 | I49: 3343 | J49: 5406 | K49: 8470
A50: Operating Profit | B50: 10820.24 | C50: 13114.4 | D50: 13217 | E50: 13767 | F50: 15418 | G50: 16685 | H50: 15785 | I50: 12159 | J50: 12423 | K50: 16818
A55: BALANCE SHEET
A56: Report Date | B56: 42460 | C56: 42825 | D56: 43190 | E56: 43555 | F56: 43921 | G56: 44286 | H56: 44651 | I56: 45016 | J56: 45382 | K56: 45747
A57: Equity Share Capital | B57: 679.18 | C57: 679.22 | D57: 679.22 | E57: 679.22 | F57: 719.54 | G57: 765.81 | H57: 765.88 | I57: 766.02 | J57: 767 | K57: 736
A58: Reserves | B58: 78273.23 | C58: 57382.67 | D58: 94748.69 | E58: 59500.34 | F58: 62358.99 | G58: 54480.91 | H58: 43795.36 | I58: 44555.77 | J58: 84151 | K58: 115408
A59: Borrowings | B59: 69359.96 | C59: 78603.98 | D59: 88950.47 | E59: 106175.34 | F59: 124787.64 | G59: 142130.57 | H59: 146449.03 | I59: 134113.44 | J59: 107264 | K59: 71540
A60: Other Liabilities | B60: 114871.75 | C60: 135914.49 | D60: 142813.43 | E60: 139348.59 | F60: 132313.22 | G60: 144192.62 | H60: 138051.22 | I60: 155239.2 | J60: 177339 | K60: 189289
...

Sheet HistoricalFs
B2: ="Historical Financial Statement - "&'Data Sheet'!B1 -> Historical Financial Statement - TATA MOTORS LTD
B3: Years | C3: ='Data Sheet'!B16 -> 42460 | D3: ='Data Sheet'!C16 -> 42825 | E3: ='Data Sheet'!D16 -> 43190 | F3: ='Data Sheet'!E16 -> 43555 | G3: ='Data Sheet'!F16 -> 43921 | H3: ='Data Sheet'!G16 -> 44286 | I3: ='Data Sheet'!H16 -> 44651 | J3: ='Data Sheet'!I16 -> 45016 | ... L3: ='Data Sheet'!K16 -> 45747 | M3: LTM
A5: # | B5: Income Statement
B6: Sales | C6: =IFERROR('Data Sheet'!B17,0) -> 273045.6 | D6: =IFERROR('Data Sheet'!C17,0) -> 269692.51 | E6: =IFERROR('Data Sheet'!D17,0) -> 291550.48 | F6: =IFERROR('Data Sheet'!E17,0) -> 301938.4 | G6: =IFERROR('Data Sheet'!F17,0) -> 261067.97 | H6: =IFERROR('Data Sheet'!G17,0) -> 249794.75 | I6: =IFERROR('Data Sheet'!H17,0) -> 278453.62 | J6: =IFERROR('Data Sheet'!I17,0) -> 345966.97 | ... L6: =IFERROR('Data Sheet'!K17,0) -> 439695 | M6: =IFERROR(SUM('Data Sheet'!H42:K42),0) -> 441609
B7: Sales Growth | C7: - | D7: =D6/C6-1 -> -0.01228033 | E7: =E6/D6-1 -> 0.081047746 | F7: =F6/E6-1 -> 0.035629919 | G7: =G6/F6-1 -> -0.13536016 | H7: =H6/G6-1 -> -0.043181168 | I7: =I6/H6-1 -> 0.11472967 | J7: =J6/I6-1 -> 0.24245815 | K7: =K6/J6-1 -> 0.25450126 | ... M7: =M6/L6-1 -> 0.0043530174
B9: COGS | C9: =IFERROR(SUM('Data Sheet'!C18,'Data Sheet'!C20:C22)-1*'Data Sheet'!C19,0) -> 205454.24 | D9: =IFERROR(SUM('Data Sheet'!D18,'Data Sheet'!D20:D22)-1*'Data Sheet'!D19,0) -> 228429.83 | E9: =IFERROR(SUM('Data Sheet'!E18,'Data Sheet'!E20:E22)-1*'Data Sheet'!E19,0) -> 242845.53 | F9: =IFERROR(SUM('Data Sheet'!F18,'Data Sheet'!F20:F22)-1*'Data Sheet'!F19,0) -> 210376.07 | G9: =IFERROR(SUM('Data Sheet'!G18,'Data Sheet'!G20:G22)-1*'Data Sheet'!G19,0) -> 195326.04 | H9: =IFERROR(SUM('Data Sheet'!H18,'Data Sheet'!H20:H22)-1*'Data Sheet'!H19,0) -> 223300.01 | I9: =IFERROR(SUM('Data Sheet'!I18,'Data Sheet'!I20:I22)-1*'Data Sheet'!I19,0) -> 274403.64 | J9: =IFERROR(SUM('Data Sheet'!J18,'Data Sheet'!J20:J22)-1*'Data Sheet'!J19,0) -> 334380 | ... L9: =IFERROR(SUM('Data Sheet'!L18,'Data Sheet'!L20:L22)-1*'Data Sheet'!L19,0) -> 0 | M9: =IFERROR(SUM('Data Sheet'!H43:K43),0) -> 384424
B10: COGS % Sales | C10: =C9/C6 -> 0.75245395 | D10: =D9/D6 -> 0.84700102 | E10: =E9/E6 -> 0.83294505 | F10: =F9/F6 -> 0.69675162 | G10: =G9/G6 -> 0.74818079 | H10: =H9/H6 -> 0.89393396 | I10: =I9/I6 -> 0.98545546 | J10: =J9/J6 -> 0.96650845 | ... M10: =M9/M6 -> 0.87050762
B12: Gross Profit | C12: =C6-C9 -> 67591.36 | D12: =D6-D9 -> 41262.68 | E12: =E6-E9 -> 48704.95 | F12: =F6-F9 -> 91562.33 | G12: =G6-G9 -> 65741.93 | H12: =H6-H9 -> 26494.74 | I12: =I6-I9 -> 4049.98 | J12: =J6-J9 -> 11586.97 | ... M12: =M6-M9 -> 57185
B13: Gross Margin | C13: =C12/C6 -> 0.24754605 | D13: =D12/D6 -> 0.15299898 | E13: =E12/E6 -> 0.16705495 | F13: =F12/F6 -> 0.30324838 | G13: =G12/G6 -> 0.25181921 | H13: =H12/H6 -> 0.10606604 | I13: =I12/I6 -> 0.014544541 | J13: =J12/J6 -> 0.03349155 | ... M13: =M12/M6 -> 0.12949238
B15: Selling & General Expenses | C15: =IFERROR(SUM('Data Sheet'!B23:B24),0) -> 29141.28 | D15: =IFERROR(SUM('Data Sheet'!C23:C24),0) -> 34649.58 | E15: =IFERROR(SUM('Data Sheet'!D23:D24),0) -> 31662.97 | F15: =IFERROR(SUM('Data Sheet'!E23:E24),0) -> 34428.54 | G15: =IFERROR(SUM('Data Sheet'!F23:F24),0) -> 32704.83 | H15: =IFERROR(SUM('Data Sheet'!G23:G24),0) -> 22181.28 | I15: =IFERROR(SUM('Data Sheet'!H23:H24),0) -> 30433.52 | J15: =IFERROR(SUM('Data Sheet'!I23:I24),0) -> 39747.53 | ... M15: =IFERROR(SUM('Data Sheet'!L23:L24),0) -> 0
B16: Selling & General Expenses | C16: =C15/C6 -> 0.10672679 | D16: =D15/D6 -> 0.1284781 | E16: =E15/E6 -> 0.10860202 | F16: =F15/F6 -> 0.11402505 | G16: =G15/G6 -> 0.12527324 | H16: =H15/H6 -> 0.088798023 | I16: =I15/I6 -> 0.10929475 | J16: =J15/J6 -> 0.11488822 | ... M16: =M15/M6 -> 0
B18: EBITDA | C18: =C12-C15 -> 38450.08 | D18: =D12-D15 -> 6613.1 | E18: =E12-E15 -> 17041.98 | F18: =F12-F15 -> 57133.79 | G18: =G12-G15 -> 33037.1 | H18: =H12-H15 -> 4313.46 | I18: =I12-I15 -> -26383.54 | J18: =J12-J15 -> -28160.56 | ... M18: =M12-M15 -> 57185
B19: EBITDA Margin | C19: =C18/C6 -> 0.14081926 | D19: =D18/D6 -> 0.024520889 | E19: =E18/E6 -> 0.058452931 | F19: =F18/F6 -> 0.18922333 | G19: =G18/G6 -> 0.12654597 | H19: =H18/H6 -> 0.017268017 | I19: =I18/I6 -> -0.094750214 | J19: =J18/J6 -> -0.081396672 | ... M19: =M18/M6 -> 0.12949238
B21: Interest | C21: =IFERROR(('Data Sheet'!B27),0) -> 4889.08 | D21: =IFERROR(('Data Sheet'!C27),0) -> 4238.01 | E21: =IFERROR(('Data Sheet'!D27),0) -> 4681.79 | F21: =IFERROR(('Data Sheet'!E27),0) -> 5758.6 | G21: =IFERROR(('Data Sheet'!F27),0) -> 7243.33 | H21: =IFERROR(('Data Sheet'!G27),0) -> 8097.17 | I21: =IFERROR(('Data Sheet'!H27),0) -> 9311.86 | J21: =IFERROR(('Data Sheet'!I27),0) -> 10225.48 | ... L21: =IFERROR(('Data Sheet'!K27),0) -> 5083 | M21: =IFERROR(SUM('Data Sheet'!H46:K46),0) -> 6317
B22: Interest % Sales | C22: =C21/C6 -> 0.017905727 | D22: =D21/D6 -> 0.01571423 | E22: =E21/E6 -> 0.016058248 | F22: =F21/F6 -> 0.019072102 | G22: =G21/G6 -> 0.027744997 | H22: =H21/H6 -> 0.032415293 | I22: =I21/I6 -> 0.033441332 | J22: =J21/J6 -> 0.029556232 | ... M22: =M21/M6 -> 0.014304509
B24: Depreciatoin | C24: =IFERROR('Data Sheet'!B45,0) -> 6071.78 | D24: =IFERROR('Data Sheet'!C45,0) -> 7050.2 | E24: =IFERROR('Data Sheet'!D45,0) -> 6633 | F24: =IFERROR('Data Sheet'!E45,0) -> 6637 | G24: =IFERROR('Data Sheet'!F45,0) -> 6850 | H24: =IFERROR('Data Sheet'!G45,0) -> 7143 | I24: =IFERROR('Data Sheet'!H45,0) -> 6574 | J24: =IFERROR('Data Sheet'!I45,0) -> 6005 | ... L24: =IFERROR('Data Sheet'!K45,0) -> 5295 | M24: =IFERROR(SUM('Data Sheet'!H45:K45),0) -> 23273
B25: Depreciatoin % on Sales | C25: =C24/C6 -> 0.022237238 | D25: =D24/D6 -> 0.026141623 | E25: =E24/E6 -> 0.022750777 | F25: =F24/F6 -> 0.021981305 | G25: =G24/G6 -> 0.026238378 | H25: =H24/H6 -> 0.028595477 | I25: =I24/I6 -> 0.023608959 | J25: =J24/J6 -> 0.017357148 | ... M25: =M24/M6 -> 0.052700466
B27: Earnings Before Tax | C27: =C18-SUM(C21,C24) -> 27489.22 | D27: =D18-SUM(D21,D24) -> -4675.11 | E27: =E18-SUM(E21,E24) -> 5727.19 | F27: =F18-SUM(F21,F24) -> 44738.19 | G27: =G18-SUM(G21,G24) -> 18943.77 | H27: =H18-SUM(H21,H24) -> -10926.71 | I27: =I18-SUM(I21,I24) -> -42269.4 | J27: =J18-SUM(J21,J24) -> -44391.04 | ... M27: =M18-SUM(M21,M24) -> 27595
B28: EBT % Sales | C28: =C27/C6 -> 0.1006763 | D28: =D27/D6 -> -0.017334964 | E28: =E27/E6 -> 0.019643905 | F28: =F27/F6 -> 0.14816992 | G28: =G27/G6 -> 0.072562597 | H28: =H27/H6 -> -0.043742753 | I28: =I27/I6 -> -0.1518005 | J28: =J27/J6 -> -0.12831005 | ... M28: =M27/M6 -> 0.062487404
B30: Tax | C30: =IFERROR('Data Sheet'!B29,0) -> 3025.05 | D30: =IFERROR('Data Sheet'!C29,0) -> 3251.23 | E30: =IFERROR('Data Sheet'!D29,0) -> 4341.93 | F30: =IFERROR('Data Sheet'!E29,0) -> -2437.45 | G30: =IFERROR('Data Sheet'!F29,0) -> 395.25 | H30: =IFERROR('Data Sheet'!G29,0) -> 2541.86 | I30: =IFERROR('Data Sheet'!H29,0) -> 4231.29 | J30: =IFERROR('Data Sheet'!I29,0) -> 704.06 | ... L30: =IFERROR('Data Sheet'!K29,0) -> 10502 | M30: =IFERROR(SUM('Data Sheet'!H48:K48),0) -> 10563
B31: Effective Tax Rate | C31: =C30/C27 -> 0.11004496 | D31: =D30/D27 -> -0.6954339 | E31: =E30/E27 -> 0.75812571 | F31: =F30/F27 -> -0.054482535 | G31: =G30/G27 -> 0.020864379 | H31: =H30/H27 -> -0.23262812 | I31: =I30/I27 -> -0.10010291 | J31: =J30/J27 -> -0.015860408 | ... M31: =M30/M27 -> 0.38278674
B33: Net Profit | C33: =IFERROR(C27-C30,0) -> 24464.17 | D33: =IFERROR(D27-D30,0) -> -7926.34 | E33: =IFERROR(E27-E30,0) -> 1385.26 | F33: =IFERROR(F27-F30,0) -> 47175.64 | G33: =IFERROR(G27-G30,0) -> 18548.52 | H33: =IFERROR(H27-H30,0) -> -13468.57 | I33: =IFERROR(I27-I30,0) -> -46500.69 | J33: =IFERROR(J27-J30,0) -> -45095.1 | ... M33: =IFERROR(M27-M30,0) -> 17032
B34: Net Margins | C34: =C33/C6 -> 0.089597379 | D34: =D33/D6 -> -0.029390286 | E34: =E33/E6 -> 0.0047513556 | F34: =F33/F6 -> 0.1562426 | G34: =G33/G6 -> 0.071048624 | H34: =H33/H6 -> -0.053918547 | I34: =I33/I6 -> -0.16699618 | J34: =J33/J6 -> -0.1303451 | ... M34: =M33/M6 -> 0.038568055
B36: No. Of Equity Shares | C36: =IFERROR('Data Sheet'!B93,0) -> 288.72 | D36: =IFERROR('Data Sheet'!C93,0) -> 288.73 | E36: =IFERROR('Data Sheet'!D93,0) -> 288.73 | F36: =IFERROR('Data Sheet'!E93,0) -> 288.73 | G36: =IFERROR('Data Sheet'!F93,0) -> 308.9 | H36: =IFERROR('Data Sheet'!G93,0) -> 332.03 | I36: =IFERROR('Data Sheet'!H93,0) -> 332.07 | J36: =IFERROR('Data Sheet'!I93,0) -> 332.13 | ... L36: =IFERROR('Data Sheet'!K93,0) -> 368.13 | M36: =L36 -> 368.13
B38: Earning per share | C38: =IFERROR(C33/C36,0) -> 84.733202 | D38: =IFERROR(D33/D36,0) -> -27.45243 | E38: =IFERROR(E33/E36,0) -> 4.7977695 | F38: =IFERROR(F33/F36,0) -> 163.39016 | G38: =IFERROR(G33/G36,0) -> 60.047006 | H38: =IFERROR(H33/H36,0) -> -40.564316 | I38: =IFERROR(I33/I36,0) -> -140.03279 | J38: =IFERROR(J33/J36,0) -> -135.77545 | ... M38: =IFERROR(M33/M36,0) -> 46.266265
B39: EPS Growth % | D39: =IFERROR(D38/C38,0) -> -0.32398669 | E39: =IFERROR(E38/D38,0) -> -0.17476666 | F39: =IFERROR(F38/E38,0) -> 34.055441 | G39: =IFERROR(G38/F38,0) -> 0.36750687 | H39: =IFERROR(H38/G38,0) -> -0.6755427 | I39: =IFERROR(I38/H38,0) -> 3.4521177 | J39: =IFERROR(J38/I38,0) -> 0.96959752 | K39: =IFERROR(K38/J38,0) -> -0.9401324 | ... M39: =IFERROR(M38/L38,0) -> 0.045401112
B41: Dividend Per Share | C41: =IFERROR('Data Sheet'!B31/HistoricalFs!C36,0) -> 0.23524522 | D41: =IFERROR('Data Sheet'!C31/HistoricalFs!D36,0) -> 0 | E41: =IFERROR('Data Sheet'!D31/HistoricalFs!E36,0) -> 0 | F41: =IFERROR('Data Sheet'!E31/HistoricalFs!F36,0) -> 0 | G41: =IFERROR('Data Sheet'!F31/HistoricalFs!G36,0) -> 0 | H41: =IFERROR('Data Sheet'!G31/HistoricalFs!H36,0) -> 0 | I41: =IFERROR('Data Sheet'!H31/HistoricalFs!I36,0) -> 0 | J41: =IFERROR('Data Sheet'!I31/HistoricalFs!J36,0) -> 2.3063861 | ... M41: =IFERROR('Data Sheet'!L31/HistoricalFs!M36,0) -> 0
B42: Dividend Payout Ratio | C42: =IFERROR(C41/C38,0) -> 0.0027763051 | D42: =IFERROR(D41/D38,0) -> 0 | E42: =IFERROR(E41/E38,0) -> 0 | F42: =IFERROR(F41/F38,0) -> 0 | G42: =IFERROR(G41/G38,0) -> 0 | H42: =IFERROR(H41/H38,0) -> 0 | I42: =IFERROR(I41/I38,0) -> 0 | J42: =IFERROR(J41/J38,0) -> -0.016986768 | ... M42: =IFERROR(M41/M38,0) -> 0
B44: Retained Ernings | C44: =IFERROR(IF(C38>C41,1-C42,0),0) -> 0.99722369 | D44: =IFERROR(IF(D38>D41,1-D42,0),0) -> 0 | E44: =IFERROR(IF(E38>E41,1-E42,0),0) -> 1 | F44: =IFERROR(IF(F38>F41,1-F42,0),0) -> 1 | G44: =IFERROR(IF(G38>G41,1-G42,0),0) -> 1 | H44: =IFERROR(IF(H38>H41,1-H42,0),0) -> 0 | I44: =IFERROR(IF(I38>I41,1-I42,0),0) -> 0 | J44: =IFERROR(IF(J38>J41,1-J42,0),0) -> 0 | ... M44: =IFERROR(IF(M38>M41,1-M42,0),0) -> 1
A46: # | B46: Balance Sheet
B47: Equity Share Capital | C47: =IFERROR('Data Sheet'!B57,0) -> 679.18 | D47: =IFERROR('Data Sheet'!C57,0) -> 679.22 | E47: =IFERROR('Data Sheet'!D57,0) -> 679.22 | F47: =IFERROR('Data Sheet'!E57,0) -> 679.22 | G47: =IFERROR('Data Sheet'!F57,0) -> 719.54 | H47: =IFERROR('Data Sheet'!G57,0) -> 765.81 | I47: =IFERROR('Data Sheet'!H57,0) -> 765.88 | J47: =IFERROR('Data Sheet'!I57,0) -> 766.02 | ... L47: =IFERROR('Data Sheet'!K57,0) -> 736
B48: Reserves | C48: =IFERROR('Data Sheet'!B58,0) -> 78273.23 | D48: =IFERROR('Data Sheet'!C58,0) -> 57382.67 | E48: =IFERROR('Data Sheet'!D58,0) -> 94748.69 | F48: =IFERROR('Data Sheet'!E58,0) -> 59500.34 | G48: =IFERROR('Data Sheet'!F58,0) -> 62358.99 | H48: =IFERROR('Data Sheet'!G58,0) -> 54480.91 | I48: =IFERROR('Data Sheet'!H58,0) -> 43795.36 | J48: =IFERROR('Data Sheet'!I58,0) -> 44555.77 | ... L48: =IFERROR('Data Sheet'!K58,0) -> 115408
B49: Borrowings | C49: =IFERROR('Data Sheet'!B59,0) -> 69359.96 | D49: =IFERROR('Data Sheet'!C59,0) -> 78603.98 | E49: =IFERROR('Data Sheet'!D59,0) -> 88950.47 | F49: =IFERROR('Data Sheet'!E59,0) -> 106175.34 | G49: =IFERROR('Data Sheet'!F59,0) -> 124787.64 | H49: =IFERROR('Data Sheet'!G59,0) -> 142130.57 | I49: =IFERROR('Data Sheet'!H59,0) -> 146449.03 | J49: =IFERROR('Data Sheet'!I59,0) -> 134113.44 | ... L49: =IFERROR('Data Sheet'!K59,0) -> 71540
B50: Other Liabilities | C50: =IFERROR('Data Sheet'!B60,0) -> 114871.75 | D50: =IFERROR('Data Sheet'!C60,0) -> 135914.49 | E50: =IFERROR('Data Sheet'!D60,0) -> 142813.43 | F50: =IFERROR('Data Sheet'!E60,0) -> 139348.59 | G50: =IFERROR('Data Sheet'!F60,0) -> 132313.22 | H50: =IFERROR('Data Sheet'!G60,0) -> 144192.62 | I50: =IFERROR('Data Sheet'!H60,0) -> 138051.22 | J50: =IFERROR('Data Sheet'!I60,0) -> 155239.2 | ... L50: =IFERROR('Data Sheet'!K60,0) -> 189289
B51: Total Liabilities | C51: =IFERROR('Data Sheet'!B61,0) -> 263184.12 | D51: =IFERROR('Data Sheet'!C61,0) -> 272580.36 | E51: =IFERROR('Data Sheet'!D61,0) -> 327191.81 | F51: =IFERROR('Data Sheet'!E61,0) -> 305703.49 | G51: =IFERROR('Data Sheet'!F61,0) -> 320179.39 | H51: =IFERROR('Data Sheet'!G61,0) -> 341569.91 | I51: =IFERROR('Data Sheet'!H61,0) -> 329061.49 | J51: =IFERROR('Data Sheet'!I61,0) -> 334674.43 | ... L51: =IFERROR('Data Sheet'!K61,0) -> 376973
B53: Fixed Assets Net Block | C53: =IFERROR('Data Sheet'!B62,0) -> 107231.76 | D53: =IFERROR('Data Sheet'!C62,0) -> 95944.08 | E53: =IFERROR('Data Sheet'!D62,0) -> 121413.86 | F53: =IFERROR('Data Sheet'!E62,0) -> 111234.47 | G53: =IFERROR('Data Sheet'!F62,0) -> 127107.14 | H53: =IFERROR('Data Sheet'!G62,0) -> 138707.61 | I53: =IFERROR('Data Sheet'!H62,0) -> 138855.45 | J53: =IFERROR('Data Sheet'!I62,0) -> 132079.76 | ... L53: =IFERROR('Data Sheet'!K62,0) -> 115697
B54: Cap Work In Progress | C54: =IFERROR('Data Sheet'!B63,0) -> 25918.94 | D54: =IFERROR('Data Sheet'!C63,0) -> 33698.84 | E54: =IFERROR('Data Sheet'!D63,0) -> 40033.5 | F54: =IFERROR('Data Sheet'!E63,0) -> 31883.84 | G54: =IFERROR('Data Sheet'!F63,0) -> 35622.29 | H54: =IFERROR('Data Sheet'!G63,0) -> 20963.93 | I54: =IFERROR('Data Sheet'!H63,0) -> 10251.09 | J54: =IFERROR('Data Sheet'!I63,0) -> 14274.5 | ... L54: =IFERROR('Data Sheet'!K63,0) -> 65806
B55: Investments | C55: =IFERROR('Data Sheet'!B64,0) -> 23767.02 | D55: =IFERROR('Data Sheet'!C64,0) -> 20337.92 | E55: =IFERROR('Data Sheet'!D64,0) -> 20812.75 | F55: =IFERROR('Data Sheet'!E64,0) -> 15770.72 | G55: =IFERROR('Data Sheet'!F64,0) -> 16308.48 | H55: =IFERROR('Data Sheet'!G64,0) -> 24620.28 | I55: =IFERROR('Data Sheet'!H64,0) -> 29379.53 | J55: =IFERROR('Data Sheet'!I64,0) -> 26379.16 | ... L55: =IFERROR('Data Sheet'!K64,0) -> 35656
B56: Other Assets | C56: =IFERROR('Data Sheet'!B65-SUM('Data Sheet'!B67:B69),0) -> 29579.36 | D56: =IFERROR('Data Sheet'!C65-SUM('Data Sheet'!C67:C69),0) -> 37360.78 | E56: =IFERROR('Data Sheet'!D65-SUM('Data Sheet'!D67:D69),0) -> 48286.86 | F56: =IFERROR('Data Sheet'!E65-SUM('Data Sheet'!E67:E69),0) -> 56155.74 | G56: =IFERROR('Data Sheet'!F65-SUM('Data Sheet'!F67:F69),0) -> 58784.94 | H56: =IFERROR('Data Sheet'!G65-SUM('Data Sheet'!G67:G69),0) -> 61717.96 | I56: =IFERROR('Data Sheet'!H65-SUM('Data Sheet'!H67:H69),0) -> 62223.77 | J56: =IFERROR('Data Sheet'!I65-SUM('Data Sheet'!I67:I69),0) -> 68432.09 | ... L56: =IFERROR('Data Sheet'!K65-SUM('Data Sheet'!K67:K69),0) -> 58463
B57: Total Non Current Assets | C57: =SUM(C53:C56) -> 186497.08 | D57: =SUM(D53:D56) -> 187341.62 | E57: =SUM(E53:E56) -> 230546.97 | F57: =SUM(F53:F56) -> 215044.77 | G57: =SUM(G53:G56) -> 237822.85 | H57: =SUM(H53:H56) -> 246009.78 | I57: =SUM(I53:I56) -> 240709.84 | J57: =SUM(J53:J56) -> 241165.51 | ... L57: =SUM(L53:L56) -> 275622
...

Sheet Ratio Analysis
B2: ="Ratio Analysis - "&'Data Sheet'!B1 -> Ratio Analysis - TATA MOTORS LTD
B3: Years | C3: ='Data Sheet'!B16 -> 42460 | D3: ='Data Sheet'!C16 -> 42825 | E3: ='Data Sheet'!D16 -> 43190 | F3: ='Data Sheet'!E16 -> 43555 | G3: ='Data Sheet'!F16 -> 43921 | H3: ='Data Sheet'!G16 -> 44286 | I3: ='Data Sheet'!H16 -> 44651 | J3: ='Data Sheet'!I16 -> 45016 | ... L3: ='Data Sheet'!K16 -> 45747 | M3: Trend | N3: Mean | O3: Median
B5: Sales Growth | D5: =IFERROR(HistoricalFs!D7,0) -> -0.01228033 | E5: =IFERROR(HistoricalFs!E7,0) -> 0.081047746 | F5: =IFERROR(HistoricalFs!F7,0) -> 0.035629919 | G5: =IFERROR(HistoricalFs!G7,0) -> -0.13536016 | H5: =IFERROR(HistoricalFs!H7,0) -> -0.043181168 | I5: =IFERROR(HistoricalFs!I7,0) -> 0.11472967 | J5: =IFERROR(HistoricalFs!J7,0) -> 0.24245815 | K5: =IFERROR(HistoricalFs!K7,0) -> 0.25450126 | L5: =IFERROR(HistoricalFs!L7,0) -> 0.013084771 | N5: =IFERROR(AVERAGE(D5:L5),) -> 0.061181096 | O5: =IFERROR(MEDIAN(C5:L5),0) -> 0.035629919
B6: EBITDA Growth | D6: =IFERROR(HistoricalFs!D18/HistoricalFs!C18-1,0) -> -0.82800816 | E6: =IFERROR(HistoricalFs!E18/HistoricalFs!D18-1,0) -> 1.5770032 | F6: =IFERROR(HistoricalFs!F18/HistoricalFs!E18-1,0) -> 2.3525324 | G6: =IFERROR(HistoricalFs!G18/HistoricalFs!F18-1,0) -> -0.421759 | H6: =IFERROR(HistoricalFs!H18/HistoricalFs!G18-1,0) -> -0.86943588 | I6: =IFERROR(HistoricalFs!I18/HistoricalFs!H18-1,0) -> -7.1165607 | J6: =IFERROR(HistoricalFs!J18/HistoricalFs!I18-1,0) -> 0.067353357 | K6: =IFERROR(HistoricalFs!K18/HistoricalFs!J18-1,0) -> -2.8250702 | L6: =IFERROR(HistoricalFs!L18/HistoricalFs!K18-1,0) -> 6.7055161 | N6: =IFERROR(AVERAGE(D6:L6),) -> -0.15093655 | O6: =IFERROR(MEDIAN(C6:L6),0) -> -0.421759
B7: EBIT Growth | D7: =IFERROR(HistoricalFs!D27/HistoricalFs!C27-1,0) -> -1.1700707 | E7: =IFERROR(HistoricalFs!E27/HistoricalFs!D27-1,0) -> -2.2250386 | F7: =IFERROR(HistoricalFs!F27/HistoricalFs!E27-1,0) -> 6.8115428 | G7: =IFERROR(HistoricalFs!G27/HistoricalFs!F27-1,0) -> -0.57656378 | H7: =IFERROR(HistoricalFs!H27/HistoricalFs!G27-1,0) -> -1.576797 | I7: =IFERROR(HistoricalFs!I27/HistoricalFs!H27-1,0) -> 2.8684471 | J7: =IFERROR(HistoricalFs!J27/HistoricalFs!I27-1,0) -> 0.050193284 | K7: =IFERROR(HistoricalFs!K27/HistoricalFs!J27-1,0) -> -1.8650845 | L7: =IFERROR(HistoricalFs!L27/HistoricalFs!K27-1,0) -> 9.0423676 | N7: =IFERROR(AVERAGE(D7:L7),) -> 1.2621107 | O7: =IFERROR(MEDIAN(C7:L7),0) -> -0.57656378
B8: Net Profit Growth | D8: =IFERROR(HistoricalFs!D33/HistoricalFs!C33-1,0) -> -1.3239979 | E8: =IFERROR(HistoricalFs!E33/HistoricalFs!D33-1,0) -> -1.1747667 | F8: =IFERROR(HistoricalFs!F33/HistoricalFs!E33-1,0) -> 33.055441 | G8: =IFERROR(HistoricalFs!G33/HistoricalFs!F33-1,0) -> -0.60681996 | H8: =IFERROR(HistoricalFs!H33/HistoricalFs!G33-1,0) -> -1.7261264 | I8: =IFERROR(HistoricalFs!I33/HistoricalFs!H33-1,0) -> 2.4525336 | J8: =IFERROR(HistoricalFs!J33/HistoricalFs!I33-1,0) -> -0.030227293 | K8: =IFERROR(HistoricalFs!K33/HistoricalFs!J33-1,0) -> -1.9408118 | L8: =IFERROR(HistoricalFs!L33/HistoricalFs!K33-1,0) -> 7.8423372 | N8: =IFERROR(AVERAGE(D8:L8),) -> 4.0608402 | O8: =IFERROR(MEDIAN(C8:L8),0) -> -0.60681996
B9: Dividend Growth | D9: =IFERROR(HistoricalFs!D41/HistoricalFs!C41-1,0) -> -1 | E9: =IFERROR(HistoricalFs!E41/HistoricalFs!D41-1,0) -> 0 | F9: =IFERROR(HistoricalFs!F41/HistoricalFs!E41-1,0) -> 0 | G9: =IFERROR(HistoricalFs!G41/HistoricalFs!F41-1,0) -> 0 | H9: =IFERROR(HistoricalFs!H41/HistoricalFs!G41-1,0) -> 0 | I9: =IFERROR(HistoricalFs!I41/HistoricalFs!H41-1,0) -> 0 | J9: =IFERROR(HistoricalFs!J41/HistoricalFs!I41-1,0) -> 0 | K9: =IFERROR(HistoricalFs!K41/HistoricalFs!J41-1,0) -> 2.001669 | L9: =IFERROR(HistoricalFs!L41/HistoricalFs!K41-1,0) -> -0.1336307 | N9: =IFERROR(AVERAGE(D9:L9),) -> 0.096448699 | O9: =IFERROR(MEDIAN(C9:L9),0) -> 0
B11: Gross Margin | C11: =IFERROR(HistoricalFs!C13,0) -> 0.24754605 | D11: =IFERROR(HistoricalFs!D13,0) -> 0.15299898 | E11: =IFERROR(HistoricalFs!E13,0) -> 0.16705495 | F11: =IFERROR(HistoricalFs!F13,0) -> 0.30324838 | G11: =IFERROR(HistoricalFs!G13,0) -> 0.25181921 | H11: =IFERROR(HistoricalFs!H13,0) -> 0.10606604 | I11: =IFERROR(HistoricalFs!I13,0) -> 0.014544541 | J11: =IFERROR(HistoricalFs!J13,0) -> 0.03349155 | ... L11: =IFERROR(HistoricalFs!L13,0) -> 1 | N11: =IFERROR(AVERAGE(C11:L11),0) -> 0.24915245 | O11: =IFERROR(MEDIAN(C11:L11),0) -> 0.19090485
B12: EBITDA Margin | C12: =IFERROR(HistoricalFs!C19,0) -> 0.14081926 | D12: =IFERROR(HistoricalFs!D19,0) -> 0.024520889 | E12: =IFERROR(HistoricalFs!E19,0) -> 0.058452931 | F12: =IFERROR(HistoricalFs!F19,0) -> 0.18922333 | G12: =IFERROR(HistoricalFs!G19,0) -> 0.12654597 | H12: =IFERROR(HistoricalFs!H19,0) -> 0.017268017 | I12: =IFERROR(HistoricalFs!I19,0) -> -0.094750214 | J12: =IFERROR(HistoricalFs!J19,0) -> -0.081396672 | ... L12: =IFERROR(HistoricalFs!L19,0) -> 0.90068115 | N12: =IFERROR(AVERAGE(C12:L12),0) -> 0.1399782 | O12: =IFERROR(MEDIAN(C12:L12),0) -> 0.088435112
B13: EBIT Margin | C13: =IFERROR((HistoricalFs!C18-HistoricalFs!C24)/HistoricalFs!C6,0) -> 0.11858202 | D13: =IFERROR((HistoricalFs!D18-HistoricalFs!D24)/HistoricalFs!D6,0) -> -0.0016207347 | E13: =IFERROR((HistoricalFs!E18-HistoricalFs!E24)/HistoricalFs!E6,0) -> 0.035702154 | F13: =IFERROR((HistoricalFs!F18-HistoricalFs!F24)/HistoricalFs!F6,0) -> 0.16724203 | G13: =IFERROR((HistoricalFs!G18-HistoricalFs!G24)/HistoricalFs!G6,0) -> 0.10030759 | H13: =IFERROR((HistoricalFs!H18-HistoricalFs!H24)/HistoricalFs!H6,0) -> -0.01132746 | I13: =IFERROR((HistoricalFs!I18-HistoricalFs!I24)/HistoricalFs!I6,0) -> -0.11835917 | J13: =IFERROR((HistoricalFs!J18-HistoricalFs!J24)/HistoricalFs!J6,0) -> -0.09875382 | ... L13: =IFERROR((HistoricalFs!L18-HistoricalFs!L24)/HistoricalFs!L6,0) -> 0.88863872 | N13: =IFERROR(AVERAGE(C13:L13),0) -> 0.1186389 | O13: =IFERROR(MEDIAN(C13:L13),0) -> 0.068004874
B14: EBT Margin | C14: =IFERROR(HistoricalFs!C28,0) -> 0.1006763 | D14: =IFERROR(HistoricalFs!D28,0) -> -0.017334964 | E14: =IFERROR(HistoricalFs!E28,0) -> 0.019643905 | F14: =IFERROR(HistoricalFs!F28,0) -> 0.14816992 | G14: =IFERROR(HistoricalFs!G28,0) -> 0.072562597 | H14: =IFERROR(HistoricalFs!H28,0) -> -0.043742753 | I14: =IFERROR(HistoricalFs!I28,0) -> -0.1518005 | J14: =IFERROR(HistoricalFs!J28,0) -> -0.12831005 | ... L14: =IFERROR(HistoricalFs!L28,0) -> 0.87707843 | N14: =IFERROR(AVERAGE(C14:L14),0) -> 0.096542349 | O14: =IFERROR(MEDIAN(C14:L14),0) -> 0.046103251
B15: Net Profit Margin | C15: =IFERROR(HistoricalFs!C34,0) -> 0.089597379 | D15: =IFERROR(HistoricalFs!D34,0) -> -0.029390286 | E15: =IFERROR(HistoricalFs!E34,0) -> 0.0047513556 | F15: =IFERROR(HistoricalFs!F34,0) -> 0.1562426 | G15: =IFERROR(HistoricalFs!G34,0) -> 0.071048624 | H15: =IFERROR(HistoricalFs!H34,0) -> -0.053918547 | I15: =IFERROR(HistoricalFs!I34,0) -> -0.16699618 | J15: =IFERROR(HistoricalFs!J34,0) -> -0.1303451 | ... L15: =IFERROR(HistoricalFs!L34,0) -> 0.85319369 | N15: =IFERROR(AVERAGE(C15:L15),0) -> 0.089193569 | O15: =IFERROR(MEDIAN(C15:L15),0) -> 0.03789999
B17: SalesExpenses%sales | C17: =IFERROR(HistoricalFs!C16,0) -> 0.10672679 | D17: =IFERROR(HistoricalFs!D16,0) -> 0.1284781 | E17: =IFERROR(HistoricalFs!E16,0) -> 0.10860202 | F17: =IFERROR(HistoricalFs!F16,0) -> 0.11402505 | G17: =IFERROR(HistoricalFs!G16,0) -> 0.12527324 | H17: =IFERROR(HistoricalFs!H16,0) -> 0.088798023 | I17: =IFERROR(HistoricalFs!I16,0) -> 0.10929475 | J17: =IFERROR(HistoricalFs!J16,0) -> 0.11488822 | ... L17: =IFERROR(HistoricalFs!L16,0) -> 0.099318846 | N17: =IFERROR(AVERAGE(C17:L17),0) -> 0.10917425 | O17: =IFERROR(MEDIAN(C17:L17),0) -> 0.10894839
B18: Depreciation%sales | C18: =IFERROR(HistoricalFs!C25,0) -> 0.022237238 | D18: =IFERROR(HistoricalFs!D25,0) -> 0.026141623 | E18: =IFERROR(HistoricalFs!E25,0) -> 0.022750777 | F18: =IFERROR(HistoricalFs!F25,0) -> 0.021981305 | G18: =IFERROR(HistoricalFs!G25,0) -> 0.026238378 | H18: =IFERROR(HistoricalFs!H25,0) -> 0.028595477 | I18: =IFERROR(HistoricalFs!I25,0) -> 0.023608959 | J18: =IFERROR(HistoricalFs!J25,0) -> 0.017357148 | ... L18: =IFERROR(HistoricalFs!L25,0) -> 0.012042439 | N18: =IFERROR(AVERAGE(C18:L18),0) -> 0.021339298 | O18: =IFERROR(MEDIAN(C18:L18),0) -> 0.022494008
B19: Operating%Sales | C19: =C13 -> 0.11858202 | D19: =D13 -> -0.0016207347 | E19: =E13 -> 0.035702154 | F19: =F13 -> 0.16724203 | G19: =G13 -> 0.10030759 | H19: =H13 -> -0.01132746 | I19: =I13 -> -0.11835917 | J19: =J13 -> -0.09875382 | ... L19: =L13 -> 0.88863872 | N19: =IFERROR(AVERAGE(C19:L19),0) -> 0.1186389 | O19: =IFERROR(MEDIAN(C19:L19),0) -> 0.068004874
B21: Return On Capital Employed | C21: =IFERROR((HistoricalFs!C18-HistoricalFs!C24)/(SUM(HistoricalFs!C47:C49)),0) -> 0.21831153 | D21: =IFERROR((HistoricalFs!D18-HistoricalFs!D24)/(SUM(HistoricalFs!D47:D49)),0) -> -0.0031983113 | E21: =IFERROR((HistoricalFs!E18-HistoricalFs!E24)/(SUM(HistoricalFs!E47:E49)),0) -> 0.05645445 | F21: =IFERROR((HistoricalFs!F18-HistoricalFs!F24)/(SUM(HistoricalFs!F47:F49)),0) -> 0.30354856 | G21: =IFERROR((HistoricalFs!G18-HistoricalFs!G24)/(SUM(HistoricalFs!G47:G49)),0) -> 0.13939231 | H21: =IFERROR((HistoricalFs!H18-HistoricalFs!H24)/(SUM(HistoricalFs!H47:H49)),0) -> -0.014335692 | I21: =IFERROR((HistoricalFs!I18-HistoricalFs!I24)/(SUM(HistoricalFs!I47:I49)),0) -> -0.17254329 | J21: =IFERROR((HistoricalFs!J18-HistoricalFs!J24)/(SUM(HistoricalFs!J47:J49)),0) -> -0.19040609 | ... L21: =IFERROR((HistoricalFs!L18-HistoricalFs!L24)/(SUM(HistoricalFs!L47:L49)),0) -> 2.0818503 | N21: =IFERROR(AVERAGE(C21:L21),0) -> 0.26584094 | O21: =IFERROR(MEDIAN(C21:L21),0) -> 0.097923381
B22: Retained Ernings% | C22: =IFERROR(HistoricalFs!C44,0) -> 0.99722369 | D22: =IFERROR(HistoricalFs!D44,0) -> 0 | E22: =IFERROR(HistoricalFs!E44,0) -> 1 | F22: =IFERROR(HistoricalFs!F44,0) -> 1 | G22: =IFERROR(HistoricalFs!G44,0) -> 1 | H22: =IFERROR(HistoricalFs!H44,0) -> 0 | I22: =IFERROR(HistoricalFs!I44,0) -> 0 | J22: =IFERROR(HistoricalFs!J44,0) -> 0 | ... L22: =IFERROR(HistoricalFs!L44,0) -> 0.99411428 | N22: =IFERROR(AVERAGE(C22:L22),0) -> 0.59371024 | O22: =IFERROR(MEDIAN(C22:L22),0) -> 0.96993933
B23: Return On Equity% | C23: =IFERROR(HistoricalFs!C33/SUM(HistoricalFs!C47:C48),0) -> 0.3098597 | D23: =IFERROR(HistoricalFs!D33/SUM(HistoricalFs!D47:D48),0) -> -0.13651536 | E23: =IFERROR(HistoricalFs!E33/SUM(HistoricalFs!E47:E48),0) -> 0.014516298 | F23: =IFERROR(HistoricalFs!F33/SUM(HistoricalFs!F47:F48),0) -> 0.78391467 | G23: =IFERROR(HistoricalFs!G33/SUM(HistoricalFs!G47:G48),0) -> 0.29405441 | H23: =IFERROR(HistoricalFs!H33/SUM(HistoricalFs!H47:H48),0) -> -0.2437895 | I23: =IFERROR(HistoricalFs!I33/SUM(HistoricalFs!I47:I48),0) -> -1.0435233 | J23: =IFERROR(HistoricalFs!J33/SUM(HistoricalFs!J47:J48),0) -> -0.99499821 | ... L23: =IFERROR(HistoricalFs!L33/SUM(HistoricalFs!L47:L48),0) -> 3.229999 | N23: =IFERROR(AVERAGE(C23:L23),0) -> 0.27131291 | O23: =IFERROR(MEDIAN(C23:L23),0) -> 0.15428535
B24: Self Sustained Growth Rate | C24: =IFERROR(C22*C23,0) -> 0.30899943 | D24: =IFERROR(D22*D23,0) -> 0 | E24: =IFERROR(E22*E23,0) -> 0.014516298 | F24: =IFERROR(F22*F23,0) -> 0.78391467 | G24: =IFERROR(G22*G23,0) -> 0.29405441 | H24: =IFERROR(H22*H23,0) -> 0 | I24: =IFERROR(I22*I23,0) -> 0 | J24: =IFERROR(J22*J23,0) -> 0 | ... L24: =IFERROR(L22*L23,0) -> 3.2109881 | N24: =IFERROR(AVERAGE(C24:L24),0) -> 0.50849876 | O24: =IFERROR(MEDIAN(C24:L24),0) -> 0.15428535
B25: Interest Coverage Ratio | C25: =(HistoricalFs!C18-HistoricalFs!C24)/HistoricalFs!C21 -> 6.6225752 | D25: =(HistoricalFs!D18-HistoricalFs!D24)/HistoricalFs!D21 -> -0.10313803 | E25: =(HistoricalFs!E18-HistoricalFs!E24)/HistoricalFs!E21 -> 2.2232907 | F25: =(HistoricalFs!F18-HistoricalFs!F24)/HistoricalFs!F21 -> 8.7689352 | G25: =(HistoricalFs!G18-HistoricalFs!G24)/HistoricalFs!G21 -> 3.6153399 | H25: =(HistoricalFs!H18-HistoricalFs!H24)/HistoricalFs!H21 -> -0.34944802 | I25: =(HistoricalFs!I18-HistoricalFs!I24)/HistoricalFs!I21 -> -3.5393079 | J25: =(HistoricalFs!J18-HistoricalFs!J24)/HistoricalFs!J21 -> -3.3412182 | ... L25: =(HistoricalFs!L18-HistoricalFs!L24)/HistoricalFs!L21 -> 76.869959 | N25: =IFERROR(AVERAGE(C25:L25),0) -> 9.6823874 | O25: =IFERROR(MEDIAN(C25:L25),0) -> 2.9193153
B27: Debtor Turnover Ratio | C27: =HistoricalFs!C6/HistoricalFs!C59 -> 20.119918 | D27: =HistoricalFs!D6/HistoricalFs!D59 -> 19.160353 | E27: =HistoricalFs!E6/HistoricalFs!E59 -> 14.655712 | F27: =HistoricalFs!F6/HistoricalFs!F59 -> 15.894699 | G27: =HistoricalFs!G6/HistoricalFs!G59 -> 23.366617 | H27: =HistoricalFs!H6/HistoricalFs!H59 -> 19.701331 | I27: =HistoricalFs!I6/HistoricalFs!I59 -> 22.379918 | J27: =HistoricalFs!J6/HistoricalFs!J59 -> 21.982948 | ... L27: =HistoricalFs!L6/HistoricalFs!L59 -> 33.189538 | N27: =IFERROR(AVERAGE(C27:L27),0) -> 21.605368 | O27: =IFERROR(MEDIAN(C27:L27),0) -> 21.051433
B28: Creditor Turnover Ratio | C28: =HistoricalFs!C6/HistoricalFs!C50 -> 2.3769604 | D28: =HistoricalFs!D6/HistoricalFs!D50 -> 1.9842808 | E28: =HistoricalFs!E6/HistoricalFs!E50 -> 2.041478 | F28: =HistoricalFs!F6/HistoricalFs!F50 -> 2.1667848 | G28: =HistoricalFs!G6/HistoricalFs!G50 -> 1.9731057 | H28: =HistoricalFs!H6/HistoricalFs!H50 -> 1.7323685 | I28: =HistoricalFs!I6/HistoricalFs!I50 -> 2.0170312 | J28: =HistoricalFs!J6/HistoricalFs!J50 -> 2.2286057 | ... L28: =HistoricalFs!L6/HistoricalFs!L50 -> 2.3228767 | N28: =IFERROR(AVERAGE(C28:L28),0) -> 2.1290872 | O28: =IFERROR(MEDIAN(C28:L28),0) -> 2.1041314
B29: Inventory Turnover | C29: =IFERROR(HistoricalFs!C6/HistoricalFs!C60,0) -> 8.3613381 | D29: =IFERROR(HistoricalFs!D6/HistoricalFs!D60,0) -> 7.6867643 | E29: =IFERROR(HistoricalFs!E6/HistoricalFs!E60,0) -> 6.9190052 | F29: =IFERROR(HistoricalFs!F6/HistoricalFs!F60,0) -> 7.7392856 | G29: =IFERROR(HistoricalFs!G6/HistoricalFs!G60,0) -> 6.9698269 | H29: =IFERROR(HistoricalFs!H6/HistoricalFs!H60,0) -> 6.9217099 | I29: =IFERROR(HistoricalFs!I6/HistoricalFs!I60,0) -> 7.9015588 | J29: =IFERROR(HistoricalFs!J6/HistoricalFs!J60,0) -> 8.4888642 | ... L29: =IFERROR(HistoricalFs!L6/HistoricalFs!L60,0) -> 9.3019738 | N29: =IFERROR(AVERAGE(C29:L29),0) -> 7.937244 | O29: =IFERROR(MEDIAN(C29:L29),0) -> 7.8204222
B30: Fixed Asset Turnover | C30: =IFERROR(HistoricalFs!C6/HistoricalFs!C53,0) -> 2.5463128 | D30: =IFERROR(HistoricalFs!D6/HistoricalFs!D53,0) -> 2.8109343 | E30: =IFERROR(HistoricalFs!E6/HistoricalFs!E53,0) -> 2.4012949 | F30: =IFERROR(HistoricalFs!F6/HistoricalFs!F53,0) -> 2.714432 | G30: =IFERROR(HistoricalFs!G6/HistoricalFs!G53,0) -> 2.0539206 | H30: =IFERROR(HistoricalFs!H6/HistoricalFs!H53,0) -> 1.8008727 | I30: =IFERROR(HistoricalFs!I6/HistoricalFs!I53,0) -> 2.0053489 | J30: =IFERROR(HistoricalFs!J6/HistoricalFs!J53,0) -> 2.6193792 | ... L30: =IFERROR(HistoricalFs!L6/HistoricalFs!L53,0) -> 3.800401 | N30: =IFERROR(AVERAGE(C30:L30),0) -> 2.6331377 | O30: =IFERROR(MEDIAN(C30:L30),0) -> 2.582846
